Workbook

Sheet Metod & intro
A1: Avoided emissions - Metod och introduktion
O2: Översikt över ark
O3: Results - analysis
O4: Base case - rivet bad med återbruk
O5: Base case - rivet bad
O6: M-TEK Manipulated
O7: M-Tett manipulated
O8: Results - analysis (t-km)
O9: Transport manipulated
O10: EPD data
O11: M-tett original
O12: M-Tek original
O13: Datagrunnlag
B34: Inkluderat
B35: Ej inkluderat
G42: * Ej inkluderat pga osäkerhet/försumbara utsläpp | Q42: * Ej inkluderat pga reparation ej antas påverka livslängd
M43: * Ej inkluderat pga osäkerhet & försumbara utsläpp

Sheet Resultat - M-tek
A1: Kalkylator - potentiella estimerade avoided emissions
A22: Antal kvadratmeter [fyll i her] | B22: 6
A25: Scenario 1 | J25: Ungått ubeboelighet | K25: M-tek ubeboelighet | L25: Bespart ubeboelighet | M25: Kostnad Rehab | N25: M-Tek KOST | O25: Bespart Kost | P25: Utslipp Rehab | Q25: M-tek Utslipp | R25: Ungåtte utslipp
B26: Materiale (A1-A4), kgCO2e | C26: Transport, kgCO2e | D26: Avfall (C1-C4), kgCO2e | E26: TOT emissions, kgCO2e
A27: Base case - Rive bad med gjenbruk | B27: ='Base case- rivet bad gjenbruk'!$R$34 -> 1248.4673 | C27: ='Transport manipulated'!J17 -> 276.48 | D27: ='Base case- rivet bad gjenbruk'!$S$34 -> 295.77719 | E27: =SUM(B27:D27) -> 1820.7245
A28: Case 1 M-tek | B28: ='M-TEK manipulated'!K45 -> 2.7722688 | C28: ='Transport manipulated'!J15 -> 9.216 | D28: ='M-TEK manipulated'!L45 -> 0.31166494 | E28: =SUM(B28:D28) -> 12.299934 | F28: Punkt 9000 uansett kvm | J28: 25 | K28: 1 | L28: =J28-K28 -> 24 | M28: {=XLOOKUP($B$22, 'Ark2'!A:A, 'Ark2'!C:C, "Ikke funnet")} -> 353000 | N28: 9000 | O28: =M28-N28 -> 344000 | P28: =E27 -> 1820.7245 | Q28: 12.3 | R28: =P28-Q28 -> 1808.4245
A29: Case 2 M-tek | B29: ='M-TEK manipulated'!$R$64 -> 191.85634 | C29: ='Transport manipulated'!J16 -> 36.864 | D29: ='M-TEK manipulated'!$S$64 -> 21.432258 | E29: =SUM(B29:D29) -> 250.1526 | F29: DROPPE
A36: Scenario 2
B37: Materiale (A1-A4), kgCO2e | C37: Transport, kgCO2e | D37: Avfall (C1-C4), kgCO2e | E37: TOT emissions, kgCO2e
A38: Base case - Rive bad med gjenbruk | B38: ='Base case- rivet bad gjenbruk'!$R$34 -> 1248.4673 | C38: ='Transport manipulated'!J17 -> 276.48 | D38: ='Base case- rivet bad gjenbruk'!$S$34 -> 295.77719 | E38: =SUM(B38:D38) -> 1820.7245
A39: Case 1 + 2 M-tek | B39: ='M-TEK manipulated'!K45+'M-TEK manipulated'!$R$64 -> 194.62861 | C39: ='Transport manipulated'!J15+'Transport manipulated'!J16 -> 46.08 | D39: ='M-TEK manipulated'!L45+'M-TEK manipulated'!$S$64 -> 21.743923 | E39: =SUM(B39:D39) -> 262.45253
A46: Scenario 3
B47: Materiale (A1-A4), kgCO2e | C47: Transport, kgCO2e | D47: Avfall (C1-C4), kgCO2e | E47: TOT emissions, kgCO2e
A48: Base case - Rive bad uten gjenbruk | B48: ='Base case- rivet bad'!$R$34 -> 1722.8765 | C48: ='Transport manipulated'!J18 -> 276.48 | D48: ='Base case- rivet bad'!$S$34 -> 300.65769 | E48: =SUM(B48:D48) -> 2300.0142
A49: Case 1 + 2 M-tek | B49: ='M-TEK manipulated'!K45+'M-TEK manipulated'!$R$64 -> 194.62861 | C49: ='Transport manipulated'!J15+'Transport manipulated'!J16 -> 46.08 | D49: ='M-TEK manipulated'!L45+'M-TEK manipulated'!$S$64 -> 21.743923 | E49: =SUM(B49:D49) -> 262.45253

Sheet Ark2
A2: 2 | B2: 25 | C2: 299000
A3: 3 | B3: 25 | C3: 312000
A4: 4 | B4: 25 | C4: 322000
A5: 5 | B5: 25 | C5: 338000
A6: 6 | B6: 25 | C6: 353000
A7: 7 | B7: 25 | C7: 368000
A8: 8 | B8: 25 | C8: 378000
A9: 9 | B9: 25 | C9: 398000
A10: 10 | B10: 25 | C10: 413000
A11: 11 | B11: 30 | C11: 428000
A12: 12 | B12: 30 | C12: 443000
A13: 13 | B13: 30 | C13: 443000
... A25: 25 | B25: 30 | C25: 543000
C26: 553000

Sheet Base case- rivet bad gjenbruk
A1: Base case: Rivet bad med gjenbruk
A3: Antal kvadratmeter | B3: ='Resultat - M-tek'!$B$22 -> 6
A5: Produkt- och viktinformation (data från M-Tett/M-Tek) | H5: EPD data | L5: Resultat per kvadratmeter | P5: Resultat per X kvadratmeter
A6: Produkt | B6: Material | C6: Vikt per kvadratmeter | D6: Vekt X m2 | E6: Enhet* | F6: Vekt 1 m2 | G6: Vekt i kg (X kvadratmeter) | H6: A1-A3 GWP (kgCO2e/kg)* | I6: A1-A4 GWP (kgCO2e/kg)* | J6: A4 GWP (kgCO2e/kg)* | K6: C1-C4 GWP (kgCO2e/kg)* | L6: A1-A3 KgCO2e/m2 | M6: A4 KgCO2e/m3 | N6: A1-A4 KgCO2e/m3 | O6: C1-C4 KgCO2e/m2 | P6: A1-A3 KgCO2e/ X m2 | Q6: A4 KgCO2e/ X m3 | R6: A1-A4 KgCO2e/X m2 | S6: C1-C4 KgCO2e/X m2 | T6: Källa | U6: Kommentar
A7: Sponplater | B7: Trevirke | C7: 10 | D7: =IF('Base case- rivet bad gjenbruk'!$E7="kg",'Base case- rivet bad gjenbruk'!$C7*$B$3,'Base case- rivet bad gjenbruk'!$C7) -> 60 | E7: kg | F7: {=IF('Base case- rivet bad gjenbruk'!$E7="kg",'Base case- rivet bad gjenbruk'!$C7,('Base case- rivet bad gjenbruk'!$C7*XLOOKUP('Base case- rivet bad gjenbruk'!$A7,'EPD data'!$A$4:$A$31,'EPD data'!$H$4:$H$31)))} -> 10 | G7: {=IF('Base case- rivet bad gjenbruk'!$E7="kg",'Base case- rivet bad gjenbruk'!$D7,('Base case- rivet bad gjenbruk'!$D7*XLOOKUP('Base case- rivet bad gjenbruk'!$A7,'EPD data'!$A$4:$A$31,'EPD data'!$H$4:$H$31)))} -> 60 | H7: {=IF('Base case- rivet bad gjenbruk'!$E7="kg",XLOOKUP(A7,'EPD data'!$A$4:$A$31,'EPD data'!$O$4:$O$31),XLOOKUP(A7,'EPD data'!$A$4:$A$31,'EPD data'!$J$4:$J$31))} -> 0.29440628 | I7: {=IF('Base case- rivet bad gjenbruk'!$E7="kg",XLOOKUP(A7,'EPD data'!$A$4:$A$31,'EPD data'!$Q$4:$Q$31),XLOOKUP('Base case- rivet bad gjenbruk'!$A7,'EPD data'!$A$4:$A$31,'EPD data'!$L$4:$L$31))} -> 0.31915984 | J7: {=IF('Base case- rivet bad gjenbruk'!$E7="kg",XLOOKUP('Base case- rivet bad gjenbruk'!$A7,'EPD data'!$A$4:$A$31,'EPD data'!$P$4:$P$31),XLOOKUP('Base case- rivet bad gjenbruk'!$A7,'EPD data'!$A$4:$A$31,'EPD data'!$K$4:$K$31))} -> 0.024753563 | K7: {=IF('Base case- rivet bad gjenbruk'!$E7="kg",XLOOKUP(A7,'EPD data'!$A$4:$A$31,'EPD data'!$R$4:$R$31),XLOOKUP('Base case- rivet bad gjenbruk'!$A7,'EPD data'!$A$4:$A$31,'EPD data'!$M$4:$M$31))} -> 0.18084906 | L7: ='Base case- rivet bad gjenbruk'!$H7*'Base case- rivet bad gjenbruk'!$C7 -> 2.9440628 | M7: ='Base case- rivet bad gjenbruk'!$J7*'Base case- rivet bad gjenbruk'!$C7 -> 0.24753563 | N7: =SUM('Base case- rivet bad gjenbruk'!$L7:$M7) -> 3.1915984 | O7: =IFERROR(K7*C7,0) -> 1.8084906 | P7: =IFERROR(H7*$D7,0) -> 17.664377 | Q7: =IFERROR('Base case- rivet bad gjenbruk'!$D7*'Base case- rivet bad gjenbruk'!$J7,0) -> 1.4852138 | R7: ='Base case- rivet bad gjenbruk'!$D7*'Base case- rivet bad gjenbruk'!$I7 -> 19.149591 | S7: ='Base case- rivet bad gjenbruk'!$K7*'Base case- rivet bad gjenbruk'!$D7 -> 10.850944 | T7: Spon | U7: .
A8: Konstruksjonsmaterialet | B8: Trevirke | C8: 13.2 | D8: =IF('Base case- rivet bad gjenbruk'!$E8="kg",'Base case- rivet bad gjenbruk'!$C8*$B$3,'Base case- rivet bad gjenbruk'!$C8) -> 79.2 | E8: kg | F8: {=IF('Base case- rivet bad gjenbruk'!$E8="kg",'Base case- rivet bad gjenbruk'!$C8,('Base case- rivet bad gjenbruk'!$C8*XLOOKUP('Base case- rivet bad gjenbruk'!$A8,'EPD data'!$A$4:$A$31,'EPD data'!$H$4:$H$31)))} -> 13.2 | G8: {=IF('Base case- rivet bad gjenbruk'!$E8="kg",'Base case- rivet bad gjenbruk'!$D8,('Base case- rivet bad gjenbruk'!$D8*XLOOKUP('Base case- rivet bad gjenbruk'!$A8,'EPD data'!$A$4:$A$31,'EPD data'!$H$4:$H$31)))} -> 79.2 | H8: {=IF('Base case- rivet bad gjenbruk'!$E8="kg",XLOOKUP(A8,'EPD data'!$A$4:$A$31,'EPD data'!$O$4:$O$31),XLOOKUP(A8,'EPD data'!$A$4:$A$31,'EPD data'!$J$4:$J$31))} -> 0.10004368 | I8: {=IF('Base case- rivet bad gjenbruk'!$E8="kg",XLOOKUP(A8,'EPD data'!$A$4:$A$31,'EPD data'!$Q$4:$Q$31),XLOOKUP('Base case- rivet bad gjenbruk'!$A8,'EPD data'!$A$4:$A$31,'EPD data'!$L$4:$L$31))} -> 0.10923688 | J8: {=IF('Base case- rivet bad gjenbruk'!$E8="kg",XLOOKUP('Base case- rivet bad gjenbruk'!$A8,'EPD data'!$A$4:$A$31,'EPD data'!$P$4:$P$31),XLOOKUP('Base case- rivet bad gjenbruk'!$A8,'EPD data'!$A$4:$A$31,'EPD data'!$K$4:$K$31))} -> 0.0091932029 | K8: {=IF('Base case- rivet bad gjenbruk'!$E8="kg",XLOOKUP(A8,'EPD data'!$A$4:$A$31,'EPD data'!$R$4:$R$31),XLOOKUP('Base case- rivet bad gjenbruk'!$A8,'EPD data'!$A$4:$A$31,'EPD data'!$M$4:$M$31))} -> 0.027639531 | L8: ='Base case- rivet bad gjenbruk'!$H8*'Base case- rivet bad gjenbruk'!$C8 -> 1.3205766 | M8: ='Base case- rivet bad gjenbruk'!$J8*'Base case- rivet bad gjenbruk'!$C8 -> 0.12135028 | N8: =SUM('Base case- rivet bad gjenbruk'!$L8:$M8) -> 1.4419268 | O8: =IFERROR(K8*C8,0) -> 0.36484181 | P8: =IFERROR(H8*$D8,0) -> 7.9234593 | Q8: =IFERROR('Base case- rivet bad gjenbruk'!$D8*'Base case- rivet bad gjenbruk'!$J8,0) -> 0.72810167 | R8: ='Base case- rivet bad gjenbruk'!$D8*'Base case- rivet bad gjenbruk'!$I8 -> 8.651561 | S8: ='Base case- rivet bad gjenbruk'!$K8*'Base case- rivet bad gjenbruk'!$D8 -> 2.1890508 | T8: Trevirke lekting | U8: .
A9: Rupanel | B9: Trevirke | C9: 36 | D9: =IF('Base case- rivet bad gjenbruk'!$E9="kg",'Base case- rivet bad gjenbruk'!$C9*$B$3,'Base case- rivet bad gjenbruk'!$C9) -> 216 | E9: kg | F9: {=IF('Base case- rivet bad gjenbruk'!$E9="kg",'Base case- rivet bad gjenbruk'!$C9,('Base case- rivet bad gjenbruk'!$C9*XLOOKUP('Base case- rivet bad gjenbruk'!$A9,'EPD data'!$A$4:$A$31,'EPD data'!$H$4:$H$31)))} -> 36 | G9: {=IF('Base case- rivet bad gjenbruk'!$E9="kg",'Base case- rivet bad gjenbruk'!$D9,('Base case- rivet bad gjenbruk'!$D9*XLOOKUP('Base case- rivet bad gjenbruk'!$A9,'EPD data'!$A$4:$A$31,'EPD data'!$H$4:$H$31)))} -> 216 | H9: {=IF('Base case- rivet bad gjenbruk'!$E9="kg",XLOOKUP(A9,'EPD data'!$A$4:$A$31,'EPD data'!$O$4:$O$31),XLOOKUP(A9,'EPD data'!$A$4:$A$31,'EPD data'!$J$4:$J$31))} -> 0.13605442 | I9: {=IF('Base case- rivet bad gjenbruk'!$E9="kg",XLOOKUP(A9,'EPD data'!$A$4:$A$31,'EPD data'!$Q$4:$Q$31),XLOOKUP('Base case- rivet bad gjenbruk'!$A9,'EPD data'!$A$4:$A$31,'EPD data'!$L$4:$L$31))} -> 0.1455102 | J9: {=IF('Base case- rivet bad gjenbruk'!$E9="kg",XLOOKUP('Base case- rivet bad gjenbruk'!$A9,'EPD data'!$A$4:$A$31,'EPD data'!$P$4:$P$31),XLOOKUP('Base case- rivet bad gjenbruk'!$A9,'EPD data'!$A$4:$A$31,'EPD data'!$K$4:$K$31))} -> 0.0094557823 | K9: {=IF('Base case- rivet bad gjenbruk'!$E9="kg",XLOOKUP(A9,'EPD data'!$A$4:$A$31,'EPD data'!$R$4:$R$31),XLOOKUP('Base case- rivet bad gjenbruk'!$A9,'EPD data'!$A$4:$A$31,'EPD data'!$M$4:$M$31))} -> 0.018975918 | L9: ='Base case- rivet bad gjenbruk'!$H9*'Base case- rivet bad gjenbruk'!$C9 -> 4.8979592 | M9: ='Base case- rivet bad gjenbruk'!$J9*'Base case- rivet bad gjenbruk'!$C9 -> 0.34040816 | N9: =SUM('Base case- rivet bad gjenbruk'!$L9:$M9) -> 5.2383673 | O9: =IFERROR(K9*C9,0) -> 0.68313306 | P9: =IFERROR(H9*$D9,0) -> 29.387755 | Q9: =IFERROR('Base case- rivet bad gjenbruk'!$D9*'Base case- rivet bad gjenbruk'!$J9,0) -> 2.042449 | R9: ='Base case- rivet bad gjenbruk'!$D9*'Base case- rivet bad gjenbruk'!$I9 -> 31.430204 | S9: ='Base case- rivet bad gjenbruk'!$K9*'Base case- rivet bad gjenbruk'!$D9 -> 4.0987984 | T9: Rupanel | U9: .
A10: Membran plater | B10: XPS og glassfiber | C10: 8.8 | D10: =IF('Base case- rivet bad gjenbruk'!$E10="kg",'Base case- rivet bad gjenbruk'!$C10*$B$3,'Base case- rivet bad gjenbruk'!$C10) -> 52.8 | E10: kg | F10: {=IF('Base case- rivet bad gjenbruk'!$E10="kg",'Base case- rivet bad gjenbruk'!$C10,('Base case- rivet bad gjenbruk'!$C10*XLOOKUP('Base case- rivet bad gjenbruk'!$A10,'EPD data'!$A$4:$A$31,'EPD data'!$H$4:$H$31)))} -> 8.8 | G10: {=IF('Base case- rivet bad gjenbruk'!$E10="kg",'Base case- rivet bad gjenbruk'!$D10,('Base case- rivet bad gjenbruk'!$D10*XLOOKUP('Base case- rivet bad gjenbruk'!$A10,'EPD data'!$A$4:$A$31,'EPD data'!$H$4:$H$31)))} -> 52.8 | H10: {=IF('Base case- rivet bad gjenbruk'!$E10="kg",XLOOKUP(A10,'EPD data'!$A$4:$A$31,'EPD data'!$O$4:$O$31),XLOOKUP(A10,'EPD data'!$A$4:$A$31,'EPD data'!$J$4:$J$31))} -> 7.5428571 | I10: {=IF('Base case- rivet bad gjenbruk'!$E10="kg",XLOOKUP(A10,'EPD data'!$A$4:$A$31,'EPD data'!$Q$4:$Q$31),XLOOKUP('Base case- rivet bad gjenbruk'!$A10,'EPD data'!$A$4:$A$31,'EPD data'!$L$4:$L$31))} -> 7.5917714 | J10: {=IF('Base case- rivet bad gjenbruk'!$E10="kg",XLOOKUP('Base case- rivet bad gjenbruk'!$A10,'EPD data'!$A$4:$A$31,'EPD data'!$P$4:$P$31),XLOOKUP('Base case- rivet bad gjenbruk'!$A10,'EPD data'!$A$4:$A$31,'EPD data'!$K$4:$K$31))} -> 0.048914286 | K10: {=IF('Base case- rivet bad gjenbruk'!$E10="kg",XLOOKUP(A10,'EPD data'!$A$4:$A$31,'EPD data'!$R$4:$R$31),XLOOKUP('Base case- rivet bad gjenbruk'!$A10,'EPD data'!$A$4:$A$31,'EPD data'!$M$4:$M$31))} -> 2.3287657 | L10: ='Base case- rivet bad gjenbruk'!$H10*'Base case- rivet bad gjenbruk'!$C10 -> 66.377143 | M10: ='Base case- rivet bad gjenbruk'!$J10*'Base case- rivet bad gjenbruk'!$C10 -> 0.43044571 | N10: =SUM('Base case- rivet bad gjenbruk'!$L10:$M10) -> 66.807589 | O10: =IFERROR(K10*C10,0) -> 20.493138 | P10: =IFERROR(H10*$D10,0) -> 398.26286 | Q10: =IFERROR('Base case- rivet bad gjenbruk'!$D10*'Base case- rivet bad gjenbruk'!$J10,0) -> 2.5826743 | R10: ='Base case- rivet bad gjenbruk'!$D10*'Base case- rivet bad gjenbruk'!$I10 -> 400.84553 | S10: ='Base case- rivet bad gjenbruk'!$K10*'Base case- rivet bad gjenbruk'!$D10 -> 122.95883 | T10: Litex våtromsplate | U10: .
A11: Isolasjon | B11: Rockwool | C11: 2.8 | D11: =IF('Base case- rivet bad gjenbruk'!$E11="kg",'Base case- rivet bad gjenbruk'!$C11*$B$3,'Base case- rivet bad gjenbruk'!$C11) -> 16.8 | E11: kg | F11: {=IF('Base case- rivet bad gjenbruk'!$E11="kg",'Base case- rivet bad gjenbruk'!$C11,('Base case- rivet bad gjenbruk'!$C11*XLOOKUP('Base case- rivet bad gjenbruk'!$A11,'EPD data'!$A$4:$A$31,'EPD data'!$H$4:$H$31)))} -> 2.8 | G11: {=IF('Base case- rivet bad gjenbruk'!$E11="kg",'Base case- rivet bad gjenbruk'!$D11,('Base case- rivet bad gjenbruk'!$D11*XLOOKUP('Base case- rivet bad gjenbruk'!$A11,'EPD data'!$A$4:$A$31,'EPD data'!$H$4:$H$31)))} -> 16.8 | H11: {=IF('Base case- rivet bad gjenbruk'!$E11="kg",XLOOKUP(A11,'EPD data'!$A$4:$A$31,'EPD data'!$O$4:$O$31),XLOOKUP(A11,'EPD data'!$A$4:$A$31,'EPD data'!$J$4:$J$31))} -> 0.97241379 | I11: {=IF('Base case- rivet bad gjenbruk'!$E11="kg",XLOOKUP(A11,'EPD data'!$A$4:$A$31,'EPD data'!$Q$4:$Q$31),XLOOKUP('Base case- rivet bad gjenbruk'!$A11,'EPD data'!$A$4:$A$31,'EPD data'!$L$4:$L$31))} -> 1.007931 | J11: {=IF('Base case- rivet bad gjenbruk'!$E11="kg",XLOOKUP('Base case- rivet bad gjenbruk'!$A11,'EPD data'!$A$4:$A$31,'EPD data'!$P$4:$P$31),XLOOKUP('Base case- rivet bad gjenbruk'!$A11,'EPD data'!$A$4:$A$31,'EPD data'!$K$4:$K$31))} -> 0.035517241 | K11: {=IF('Base case- rivet bad gjenbruk'!$E11="kg",XLOOKUP(A11,'EPD data'!$A$4:$A$31,'EPD data'!$R$4:$R$31),XLOOKUP('Base case- rivet bad gjenbruk'!$A11,'EPD data'!$A$4:$A$31,'EPD data'!$M$4:$M$31))} -> 0.017517241 | L11: ='Base case- rivet bad gjenbruk'!$H11*'Base case- rivet bad gjenbruk'!$C11 -> 2.7227586 | M11: ='Base case- rivet bad gjenbruk'!$J11*'Base case- rivet bad gjenbruk'!$C11 -> 0.099448276 | N11: =SUM('Base case- rivet bad gjenbruk'!$L11:$M11) -> 2.8222069 | O11: =IFERROR(K11*C11,0) -> 0.049048276 | P11: =IFERROR(H11*$D11,0) -> 16.336552 | Q11: =IFERROR('Base case- rivet bad gjenbruk'!$D11*'Base case- rivet bad gjenbruk'!$J11,0) -> 0.59668966 | R11: ='Base case- rivet bad gjenbruk'!$D11*'Base case- rivet bad gjenbruk'!$I11 -> 16.933241 | S11: ='Base case- rivet bad gjenbruk'!$K11*'Base case- rivet bad gjenbruk'!$D11 -> 0.29428966 | T11: rockwool | U11: .
A12: Sparkel | B12: Jotun våtromsparkel | C12: 1 | D12: =IF('Base case- rivet bad gjenbruk'!$E12="kg",'Base case- rivet bad gjenbruk'!$C12*$B$3,'Base case- rivet bad gjenbruk'!$C12) -> 6 | E12: kg | F12: {=IF('Base case- rivet bad gjenbruk'!$E12="kg",'Base case- rivet bad gjenbruk'!$C12,('Base case- rivet bad gjenbruk'!$C12*XLOOKUP('Base case- rivet bad gjenbruk'!$A12,'EPD data'!$A$4:$A$31,'EPD data'!$H$4:$H$31)))} -> 1 | G12: {=IF('Base case- rivet bad gjenbruk'!$E12="kg",'Base case- rivet bad gjenbruk'!$D12,('Base case- rivet bad gjenbruk'!$D12*XLOOKUP('Base case- rivet bad gjenbruk'!$A12,'EPD data'!$A$4:$A$31,'EPD data'!$H$4:$H$31)))} -> 6 | H12: {=IF('Base case- rivet bad gjenbruk'!$E12="kg",XLOOKUP(A12,'EPD data'!$A$4:$A$31,'EPD data'!$O$4:$O$31),XLOOKUP(A12,'EPD data'!$A$4:$A$31,'EPD data'!$J$4:$J$31))} -> 2.6628 | I12: {=IF('Base case- rivet bad gjenbruk'!$E12="kg",XLOOKUP(A12,'EPD data'!$A$4:$A$31,'EPD data'!$Q$4:$Q$31),XLOOKUP('Base case- rivet bad gjenbruk'!$A12,'EPD data'!$A$4:$A$31,'EPD data'!$L$4:$L$31))} -> 2.6628 | J12: {=IF('Base case- rivet bad gjenbruk'!$E12="kg",XLOOKUP('Base case- rivet bad gjenbruk'!$A12,'EPD data'!$A$4:$A$31,'EPD data'!$P$4:$P$31),XLOOKUP('Base case- rivet bad gjenbruk'!$A12,'EPD data'!$A$4:$A$31,'EPD data'!$K$4:$K$31))} -> 0 | K12: {=IF('Base case- rivet bad gjenbruk'!$E12="kg",XLOOKUP(A12,'EPD data'!$A$4:$A$31,'EPD data'!$R$4:$R$31),XLOOKUP('Base case- rivet bad gjenbruk'!$A12,'EPD data'!$A$4:$A$31,'EPD data'!$M$4:$M$31))} -> 0 | L12: ='Base case- rivet bad gjenbruk'!$H12*'Base case- rivet bad gjenbruk'!$C12 -> 2.6628 | M12: ='Base case- rivet bad gjenbruk'!$J12*'Base case- rivet bad gjenbruk'!$C12 -> 0 | N12: =SUM('Base case- rivet bad gjenbruk'!$L12:$M12) -> 2.6628 | O12: =IFERROR(K12*C12,0) -> 0 | P12: =IFERROR(H12*$D12,0) -> 15.9768 | Q12: =IFERROR('Base case- rivet bad gjenbruk'!$D12*'Base case- rivet bad gjenbruk'!$J12,0) -> 0 | R12: ='Base case- rivet bad gjenbruk'!$D12*'Base case- rivet bad gjenbruk'!$I12 -> 15.9768 | S12: =IFERROR('Base case- rivet bad gjenbruk'!$K12*'Base case- rivet bad gjenbruk'!$D12,0) -> 0 | T12: jotun våtromsparkel | U12: .
A13: Baderomsstøp | B13: Avrettingsmasse | C13: 22.5 | D13: =IF('Base case- rivet bad gjenbruk'!$E13="kg",'Base case- rivet bad gjenbruk'!$C13*$B$3,'Base case- rivet bad gjenbruk'!$C13) -> 135 | E13: kg | F13: {=IF('Base case- rivet bad gjenbruk'!$E13="kg",'Base case- rivet bad gjenbruk'!$C13,('Base case- rivet bad gjenbruk'!$C13*XLOOKUP('Base case- rivet bad gjenbruk'!$A13,'EPD data'!$A$4:$A$31,'EPD data'!$H$4:$H$31)))} -> 22.5 | G13: {=IF('Base case- rivet bad gjenbruk'!$E13="kg",'Base case- rivet bad gjenbruk'!$D13,('Base case- rivet bad gjenbruk'!$D13*XLOOKUP('Base case- rivet bad gjenbruk'!$A13,'EPD data'!$A$4:$A$31,'EPD data'!$H$4:$H$31)))} -> 135 | H13: {=IF('Base case- rivet bad gjenbruk'!$E13="kg",XLOOKUP(A13,'EPD data'!$A$4:$A$31,'EPD data'!$O$4:$O$31),XLOOKUP(A13,'EPD data'!$A$4:$A$31,'EPD data'!$J$4:$J$31))} -> 0.171 | I13: {=IF('Base case- rivet bad gjenbruk'!$E13="kg",XLOOKUP(A13,'EPD data'!$A$4:$A$31,'EPD data'!$Q$4:$Q$31),XLOOKUP('Base case- rivet bad gjenbruk'!$A13,'EPD data'!$A$4:$A$31,'EPD data'!$L$4:$L$31))} -> 0.171 | J13: {=IF('Base case- rivet bad gjenbruk'!$E13="kg",XLOOKUP('Base case- rivet bad gjenbruk'!$A13,'EPD data'!$A$4:$A$31,'EPD data'!$P$4:$P$31),XLOOKUP('Base case- rivet bad gjenbruk'!$A13,'EPD data'!$A$4:$A$31,'EPD data'!$K$4:$K$31))} -> 0 | K13: {=IF('Base case- rivet bad gjenbruk'!$E13="kg",XLOOKUP(A13,'EPD data'!$A$4:$A$31,'EPD data'!$R$4:$R$31),XLOOKUP('Base case- rivet bad gjenbruk'!$A13,'EPD data'!$A$4:$A$31,'EPD data'!$M$4:$M$31))} -> 0 | L13: ='Base case- rivet bad gjenbruk'!$H13*'Base case- rivet bad gjenbruk'!$C13 -> 3.8475 | M13: ='Base case- rivet bad gjenbruk'!$J13*'Base case- rivet bad gjenbruk'!$C13 -> 0 | N13: =SUM('Base case- rivet bad gjenbruk'!$L13:$M13) -> 3.8475 | O13: =IFERROR(K13*C13,0) -> 0 | P13: =IFERROR(H13*$D13,0) -> 23.085 | Q13: =IFERROR('Base case- rivet bad gjenbruk'!$D13*'Base case- rivet bad gjenbruk'!$J13,0) -> 0 | R13: ='Base case- rivet bad gjenbruk'!$D13*'Base case- rivet bad gjenbruk'!$I13 -> 23.085 | S13: =IFERROR('Base case- rivet bad gjenbruk'!$K13*'Base case- rivet bad gjenbruk'!$D13,0) -> 0 | T13: avrettingsmasse (Proplan Basic) | U13: .
A14: Armering | B14: Stål | C14: 2.4 | D14: =IF('Base case- rivet bad gjenbruk'!$E14="kg",'Base case- rivet bad gjenbruk'!$C14*$B$3,'Base case- rivet bad gjenbruk'!$C14) -> 14.4 | E14: kg | F14: {=IF('Base case- rivet bad gjenbruk'!$E14="kg",'Base case- rivet bad gjenbruk'!$C14,('Base case- rivet bad gjenbruk'!$C14*XLOOKUP('Base case- rivet bad gjenbruk'!$A14,'EPD data'!$A$4:$A$31,'EPD data'!$H$4:$H$31)))} -> 2.4 | G14: {=IF('Base case- rivet bad gjenbruk'!$E14="kg",'Base case- rivet bad gjenbruk'!$D14,('Base case- rivet bad gjenbruk'!$D14*XLOOKUP('Base case- rivet bad gjenbruk'!$A14,'EPD data'!$A$4:$A$31,'EPD data'!$H$4:$H$31)))} -> 14.4 | H14: {=IF('Base case- rivet bad gjenbruk'!$E14="kg",XLOOKUP(A14,'EPD data'!$A$4:$A$31,'EPD data'!$O$4:$O$31),XLOOKUP(A14,'EPD data'!$A$4:$A$31,'EPD data'!$J$4:$J$31))} -> 0.393 | I14: {=IF('Base case- rivet bad gjenbruk'!$E14="kg",XLOOKUP(A14,'EPD data'!$A$4:$A$31,'EPD data'!$Q$4:$Q$31),XLOOKUP('Base case- rivet bad gjenbruk'!$A14,'EPD data'!$A$4:$A$31,'EPD data'!$L$4:$L$31))} -> 0.4032 | J14: {=IF('Base case- rivet bad gjenbruk'!$E14="kg",XLOOKUP('Base case- rivet bad gjenbruk'!$A14,'EPD data'!$A$4:$A$31,'EPD data'!$P$4:$P$31),XLOOKUP('Base case- rivet bad gjenbruk'!$A14,'EPD data'!$A$4:$A$31,'EPD data'!$K$4:$K$31))} -> 0.0102 | K14: {=IF('Base case- rivet bad gjenbruk'!$E14="kg",XLOOKUP(A14,'EPD data'!$A$4:$A$31,'EPD data'!$R$4:$R$31),XLOOKUP('Base case- rivet bad gjenbruk'!$A14,'EPD data'!$A$4:$A$31,'EPD data'!$M$4:$M$31))} -> 0.067994 | L14: ='Base case- rivet bad gjenbruk'!$H14*'Base case- rivet bad gjenbruk'!$C14 -> 0.9432 | M14: ='Base case- rivet bad gjenbruk'!$J14*'Base case- rivet bad gjenbruk'!$C14 -> 0.02448 | N14: =SUM('Base case- rivet bad gjenbruk'!$L14:$M14) -> 0.96768 | O14: =IFERROR(K14*C14,0) -> 0.1631856 | P14: =IFERROR(H14*$D14,0) -> 5.6592 | Q14: =IFERROR('Base case- rivet bad gjenbruk'!$D14*'Base case- rivet bad gjenbruk'!$J14,0) -> 0.14688 | R14: ='Base case- rivet bad gjenbruk'!$D14*'Base case- rivet bad gjenbruk'!$I14 -> 5.80608 | S14: ='Base case- rivet bad gjenbruk'!$K14*'Base case- rivet bad gjenbruk'!$D14 -> 0.9791136 | T14: Armeringsnett | U14: .
A15: Varmekabler med feste | B15: Plast og kobber | C15: 2.4 | D15: =IF('Base case- rivet bad gjenbruk'!$E15="kg",'Base case- rivet bad gjenbruk'!$C15*$B$3,'Base case- rivet bad gjenbruk'!$C15) -> 14.4 | E15: kg | F15: {=IF('Base case- rivet bad gjenbruk'!$E15="kg",'Base case- rivet bad gjenbruk'!$C15,('Base case- rivet bad gjenbruk'!$C15*XLOOKUP('Base case- rivet bad gjenbruk'!$A15,'EPD data'!$A$4:$A$31,'EPD data'!$H$4:$H$31)))} -> 2.4 | G15: {=IF('Base case- rivet bad gjenbruk'!$E15="kg",'Base case- rivet bad gjenbruk'!$D15,('Base case- rivet bad gjenbruk'!$D15*XLOOKUP('Base case- rivet bad gjenbruk'!$A15,'EPD data'!$A$4:$A$31,'EPD data'!$H$4:$H$31)))} -> 14.4 | H15: {=IF('Base case- rivet bad gjenbruk'!$E15="kg",XLOOKUP(A15,'EPD data'!$A$4:$A$31,'EPD data'!$O$4:$O$31),XLOOKUP(A15,'EPD data'!$A$4:$A$31,'EPD data'!$J$4:$J$31))} -> 4.5378151 | I15: {=IF('Base case- rivet bad gjenbruk'!$E15="kg",XLOOKUP(A15,'EPD data'!$A$4:$A$31,'EPD data'!$Q$4:$Q$31),XLOOKUP('Base case- rivet bad gjenbruk'!$A15,'EPD data'!$A$4:$A$31,'EPD data'!$L$4:$L$31))} -> 4.6011204 | J15: {=IF('Base case- rivet bad gjenbruk'!$E15="kg",XLOOKUP('Base case- rivet bad gjenbruk'!$A15,'EPD data'!$A$4:$A$31,'EPD data'!$P$4:$P$31),XLOOKUP('Base case- rivet bad gjenbruk'!$A15,'EPD data'!$A$4:$A$31,'EPD data'!$K$4:$K$31))} -> 0.063305322 | K15: {=IF('Base case- rivet bad gjenbruk'!$E15="kg",XLOOKUP(A15,'EPD data'!$A$4:$A$31,'EPD data'!$R$4:$R$31),XLOOKUP('Base case- rivet bad gjenbruk'!$A15,'EPD data'!$A$4:$A$31,'EPD data'!$M$4:$M$31))} -> 0.8642409 | L15: ='Base case- rivet bad gjenbruk'!$H15*'Base case- rivet bad gjenbruk'!$C15 -> 10.890756 | M15: ='Base case- rivet bad gjenbruk'!$J15*'Base case- rivet bad gjenbruk'!$C15 -> 0.15193277 | N15: =SUM('Base case- rivet bad gjenbruk'!$L15:$M15) -> 11.042689 | O15: =IFERROR(K15*C15,0) -> 2.0741782 | P15: =IFERROR(H15*$D15,0) -> 65.344538 | Q15: =IFERROR('Base case- rivet bad gjenbruk'!$D15*'Base case- rivet bad gjenbruk'!$J15,0) -> 0.91159664 | R15: ='Base case- rivet bad gjenbruk'!$D15*'Base case- rivet bad gjenbruk'!$I15 -> 66.256134 | S15: ='Base case- rivet bad gjenbruk'!$K15*'Base case- rivet bad gjenbruk'!$D15 -> 12.445069 | T15: Varmekabel ØS varme | U15: .
A16: Gips i taket | B16: Gips | C16: 18.6 | D16: =IF('Base case- rivet bad gjenbruk'!$E16="kg",'Base case- rivet bad gjenbruk'!$C16*$B$3,'Base case- rivet bad gjenbruk'!$C16) -> 111.6 | E16: kg | F16: {=IF('Base case- rivet bad gjenbruk'!$E16="kg",'Base case- rivet bad gjenbruk'!$C16,('Base case- rivet bad gjenbruk'!$C16*XLOOKUP('Base case- rivet bad gjenbruk'!$A16,'EPD data'!$A$4:$A$31,'EPD data'!$H$4:$H$31)))} -> 18.6 | G16: {=IF('Base case- rivet bad gjenbruk'!$E16="kg",'Base case- rivet bad gjenbruk'!$D16,('Base case- rivet bad gjenbruk'!$D16*XLOOKUP('Base case- rivet bad gjenbruk'!$A16,'EPD data'!$A$4:$A$31,'EPD data'!$H$4:$H$31)))} -> 111.6 | H16: {=IF('Base case- rivet bad gjenbruk'!$E16="kg",XLOOKUP(A16,'EPD data'!$A$4:$A$31,'EPD data'!$O$4:$O$31),XLOOKUP(A16,'EPD data'!$A$4:$A$31,'EPD data'!$J$4:$J$31))} -> 0.17919531 | I16: {=IF('Base case- rivet bad gjenbruk'!$E16="kg",XLOOKUP(A16,'EPD data'!$A$4:$A$31,'EPD data'!$Q$4:$Q$31),XLOOKUP('Base case- rivet bad gjenbruk'!$A16,'EPD data'!$A$4:$A$31,'EPD data'!$L$4:$L$31))} -> 0.20872309 | J16: {=IF('Base case- rivet bad gjenbruk'!$E16="kg",XLOOKUP('Base case- rivet bad gjenbruk'!$A16,'EPD data'!$A$4:$A$31,'EPD data'!$P$4:$P$31),XLOOKUP('Base case- rivet bad gjenbruk'!$A16,'EPD data'!$A$4:$A$31,'EPD data'!$K$4:$K$31))} -> 0.029527781 | K16: {=IF('Base case- rivet bad gjenbruk'!$E16="kg",XLOOKUP(A16,'EPD data'!$A$4:$A$31,'EPD data'!$R$4:$R$31),XLOOKUP('Base case- rivet bad gjenbruk'!$A16,'EPD data'!$A$4:$A$31,'EPD data'!$M$4:$M$31))} -> 0.10180781 | L16: ='Base case- rivet bad gjenbruk'!$H16*'Base case- rivet bad gjenbruk'!$C16 -> 3.3330328 | M16: ='Base case- rivet bad gjenbruk'!$J16*'Base case- rivet bad gjenbruk'!$C16 -> 0.54921672 | N16: =SUM('Base case- rivet bad gjenbruk'!$L16:$M16) -> 3.8822495 | O16: =IFERROR(K16*C16,0) -> 1.8936253 | P16: =IFERROR(H16*$D16,0) -> 19.998197 | Q16: =IFERROR('Base case- rivet bad gjenbruk'!$D16*'Base case- rivet bad gjenbruk'!$J16,0) -> 3.2953003 | R16: ='Base case- rivet bad gjenbruk'!$D16*'Base case- rivet bad gjenbruk'!$I16 -> 23.293497 | S16: ='Base case- rivet bad gjenbruk'!$K16*'Base case- rivet bad gjenbruk'!$D16 -> 11.361752 | T16: Gipsplate | U16: .
A17: Masnejtter og tape | B17: Plast | C17: 0.2 | D17: =IF('Base case- rivet bad gjenbruk'!$E17="kg",'Base case- rivet bad gjenbruk'!$C17*$B$3,'Base case- rivet bad gjenbruk'!$C17) -> 1.2 | E17: kg | F17: {=IF('Base case- rivet bad gjenbruk'!$E17="kg",'Base case- rivet bad gjenbruk'!$C17,('Base case- rivet bad gjenbruk'!$C17*XLOOKUP('Base case- rivet bad gjenbruk'!$A17,'EPD data'!$A$4:$A$31,'EPD data'!$H$4:$H$31)))} -> 0.2 | G17: {=IF('Base case- rivet bad gjenbruk'!$E17="kg",'Base case- rivet bad gjenbruk'!$D17,('Base case- rivet bad gjenbruk'!$D17*XLOOKUP('Base case- rivet bad gjenbruk'!$A17,'EPD data'!$A$4:$A$31,'EPD data'!$H$4:$H$31)))} -> 1.2 | H17: {=IF('Base case- rivet bad gjenbruk'!$E17="kg",XLOOKUP(A17,'EPD data'!$A$4:$A$31,'EPD data'!$O$4:$O$31),XLOOKUP(A17,'EPD data'!$A$4:$A$31,'EPD data'!$J$4:$J$31))} -> 4.0233 | I17: {=IF('Base case- rivet bad gjenbruk'!$E17="kg",XLOOKUP(A17,'EPD data'!$A$4:$A$31,'EPD data'!$Q$4:$Q$31),XLOOKUP('Base case- rivet bad gjenbruk'!$A17,'EPD data'!$A$4:$A$31,'EPD data'!$L$4:$L$31))} -> 4.0233 | J17: {=IF('Base case- rivet bad gjenbruk'!$E17="kg",XLOOKUP('Base case- rivet bad gjenbruk'!$A17,'EPD data'!$A$4:$A$31,'EPD data'!$P$4:$P$31),XLOOKUP('Base case- rivet bad gjenbruk'!$A17,'EPD data'!$A$4:$A$31,'EPD data'!$K$4:$K$31))} -> 0 | K17: {=IF('Base case- rivet bad gjenbruk'!$E17="kg",XLOOKUP(A17,'EPD data'!$A$4:$A$31,'EPD data'!$R$4:$R$31),XLOOKUP('Base case- rivet bad gjenbruk'!$A17,'EPD data'!$A$4:$A$31,'EPD data'!$M$4:$M$31))} -> 0 | L17: ='Base case- rivet bad gjenbruk'!$H17*'Base case- rivet bad gjenbruk'!$C17 -> 0.80466 | M17: ='Base case- rivet bad gjenbruk'!$J17*'Base case- rivet bad gjenbruk'!$C17 -> 0 | N17: =SUM('Base case- rivet bad gjenbruk'!$L17:$M17) -> 0.80466 | O17: =IFERROR(K17*C17,0) -> 0 | P17: =IFERROR(H17*$D17,0) -> 4.82796 | Q17: =IFERROR('Base case- rivet bad gjenbruk'!$D17*'Base case- rivet bad gjenbruk'!$J17,0) -> 0 | R17: ='Base case- rivet bad gjenbruk'!$D17*'Base case- rivet bad gjenbruk'!$I17 -> 4.82796 | S17: =IFERROR(O17*$D$17,0) -> 0 | T17: slukmansjett (PCI_Pecitape) | U17: Notera: utsläpp estimerat per material då ingen EPD fanns tillgänglig. Därav är A4+C1-C4 ej inkluderat.
A18: Smøremembran | C18: 2.4 | D18: =IF('Base case- rivet bad gjenbruk'!$E18="kg",'Base case- rivet bad gjenbruk'!$C18*$B$3,'Base case- rivet bad gjenbruk'!$C18) -> 14.4 | E18: kg | F18: {=IF('Base case- rivet bad gjenbruk'!$E18="kg",'Base case- rivet bad gjenbruk'!$C18,('Base case- rivet bad gjenbruk'!$C18*XLOOKUP('Base case- rivet bad gjenbruk'!$A18,'EPD data'!$A$4:$A$31,'EPD data'!$H$4:$H$31)))} -> 2.4 | G18: {=IF('Base case- rivet bad gjenbruk'!$E18="kg",'Base case- rivet bad gjenbruk'!$D18,('Base case- rivet bad gjenbruk'!$D18*XLOOKUP('Base case- rivet bad gjenbruk'!$A18,'EPD data'!$A$4:$A$31,'EPD data'!$H$4:$H$31)))} -> 14.4 | H18: {=IF('Base case- rivet bad gjenbruk'!$E18="kg",XLOOKUP(A18,'EPD data'!$A$4:$A$31,'EPD data'!$O$4:$O$31),XLOOKUP(A18,'EPD data'!$A$4:$A$31,'EPD data'!$J$4:$J$31))} -> 1.36 | I18: {=IF('Base case- rivet bad gjenbruk'!$E18="kg",XLOOKUP(A18,'EPD data'!$A$4:$A$31,'EPD data'!$Q$4:$Q$31),XLOOKUP('Base case- rivet bad gjenbruk'!$A18,'EPD data'!$A$4:$A$31,'EPD data'!$L$4:$L$31))} -> 1.4106 | J18: {=IF('Base case- rivet bad gjenbruk'!$E18="kg",XLOOKUP('Base case- rivet bad gjenbruk'!$A18,'EPD data'!$A$4:$A$31,'EPD data'!$P$4:$P$31),XLOOKUP('Base case- rivet bad gjenbruk'!$A18,'EPD data'!$A$4:$A$31,'EPD data'!$K$4:$K$31))} -> 0.0506 | K18: {=IF('Base case- rivet bad gjenbruk'!$E18="kg",XLOOKUP(A18,'EPD data'!$A$4:$A$31,'EPD data'!$R$4:$R$31),XLOOKUP('Base case- rivet bad gjenbruk'!$A18,'EPD data'!$A$4:$A$31,'EPD data'!$M$4:$M$31))} -> 0.441066 | L18: ='Base case- rivet bad gjenbruk'!$H18*'Base case- rivet bad gjenbruk'!$C18 -> 3.264 | M18: ='Base case- rivet bad gjenbruk'!$J18*'Base case- rivet bad gjenbruk'!$C18 -> 0.12144 | N18: =SUM('Base case- rivet bad gjenbruk'!$L18:$M18) -> 3.38544 | O18: =IFERROR(K18*C18,0) -> 1.0585584 | P18: =IFERROR(H18*$D18,0) -> 19.584 | Q18: =IFERROR('Base case- rivet bad gjenbruk'!$D18*'Base case- rivet bad gjenbruk'!$J18,0) -> 0.72864 | R18: ='Base case- rivet bad gjenbruk'!$D18*'Base case- rivet bad gjenbruk'!$I18 -> 20.31264 | S18: ='Base case- rivet bad gjenbruk'!$K18*'Base case- rivet bad gjenbruk'!$D18 -> 6.3513504 | T18: PCI membran (Lastogum) | U18: .
A19: Vann og avløpsrør | B19: Plast | C19: 4.8 | D19: =IF('Base case- rivet bad gjenbruk'!$E19="kg",'Base case- rivet bad gjenbruk'!$C19*$B$3,'Base case- rivet bad gjenbruk'!$C19) -> 28.8 | E19: kg | F19: {=IF('Base case- rivet bad gjenbruk'!$E19="kg",'Base case- rivet bad gjenbruk'!$C19,('Base case- rivet bad gjenbruk'!$C19*XLOOKUP('Base case- rivet bad gjenbruk'!$A19,'EPD data'!$A$4:$A$31,'EPD data'!$H$4:$H$31)))} -> 4.8 | G19: {=IF('Base case- rivet bad gjenbruk'!$E19="kg",'Base case- rivet bad gjenbruk'!$D19,('Base case- rivet bad gjenbruk'!$D19*XLOOKUP('Base case- rivet bad gjenbruk'!$A19,'EPD data'!$A$4:$A$31,'EPD data'!$H$4:$H$31)))} -> 28.8 | H19: {=IF('Base case- rivet bad gjenbruk'!$E19="kg",XLOOKUP(A19,'EPD data'!$A$4:$A$31,'EPD data'!$O$4:$O$31),XLOOKUP(A19,'EPD data'!$A$4:$A$31,'EPD data'!$J$4:$J$31))} -> 3.1 | I19: {=IF('Base case- rivet bad gjenbruk'!$E19="kg",XLOOKUP(A19,'EPD data'!$A$4:$A$31,'EPD data'!$Q$4:$Q$31),XLOOKUP('Base case- rivet bad gjenbruk'!$A19,'EPD data'!$A$4:$A$31,'EPD data'!$L$4:$L$31))} -> 3.344 | J19: {=IF('Base case- rivet bad gjenbruk'!$E19="kg",XLOOKUP('Base case- rivet bad gjenbruk'!$A19,'EPD data'!$A$4:$A$31,'EPD data'!$P$4:$P$31),XLOOKUP('Base case- rivet bad gjenbruk'!$A19,'EPD data'!$A$4:$A$31,'EPD data'!$K$4:$K$31))} -> 0.244 | K19: {=IF('Base case- rivet bad gjenbruk'!$E19="kg",XLOOKUP(A19,'EPD data'!$A$4:$A$31,'EPD data'!$R$4:$R$31),XLOOKUP('Base case- rivet bad gjenbruk'!$A19,'EPD data'!$A$4:$A$31,'EPD data'!$M$4:$M$31))} -> 3.03866 | L19: ='Base case- rivet bad gjenbruk'!$H19*'Base case- rivet bad gjenbruk'!$C19 -> 14.88 | M19: ='Base case- rivet bad gjenbruk'!$J19*'Base case- rivet bad gjenbruk'!$C19 -> 1.1712 | N19: =SUM('Base case- rivet bad gjenbruk'!$L19:$M19) -> 16.0512 | O19: =IFERROR(K19*C19,0) -> 14.585568 | P19: =IFERROR(H19*$D19,0) -> 89.28 | Q19: =IFERROR('Base case- rivet bad gjenbruk'!$D19*'Base case- rivet bad gjenbruk'!$J19,0) -> 7.0272 | R19: ='Base case- rivet bad gjenbruk'!$D19*'Base case- rivet bad gjenbruk'!$I19 -> 96.3072 | S19: ='Base case- rivet bad gjenbruk'!$K19*'Base case- rivet bad gjenbruk'!$D19 -> 87.513408 | T19: Rør i rør system roth mulitiplex | U19: .
A20: Elektro, ledninger og stikk og belysning | B20: Plast, kobber stål | C20: See below | D20: =IF('Base case- rivet bad gjenbruk'!$E20="kg",'Base case- rivet bad gjenbruk'!$C20*$B$3,'Base case- rivet bad gjenbruk'!$C20) -> See below | N20: =SUM('Base case- rivet bad gjenbruk'!$L20:$M20) -> 0 | Q20: =IFERROR('Base case- rivet bad gjenbruk'!$D20*'Base case- rivet bad gjenbruk'!$J20,0) -> 0 | U20: .
A21: Downlight | B21: Plast, kobber stål | C21: =IF(B3<=12,4,IF(B3<18,6,IF(B3<=24,8,IF(B3<=28,10,IF(B3<=32,12,12))))) -> 4 | D21: =IF('Base case- rivet bad gjenbruk'!$E21="kg",'Base case- rivet bad gjenbruk'!$C21*$B$3,'Base case- rivet bad gjenbruk'!$C21) -> 4 | E21: pcs | F21: {=IF('Base case- rivet bad gjenbruk'!$E21="kg",'Base case- rivet bad gjenbruk'!$C21,('Base case- rivet bad gjenbruk'!$C21*XLOOKUP('Base case- rivet bad gjenbruk'!$A21,'EPD data'!$A$4:$A$31,'EPD data'!$H$4:$H$31)))} -> 5.48 | G21: {=IF('Base case- rivet bad gjenbruk'!$E21="kg",'Base case- rivet bad gjenbruk'!$D21,('Base case- rivet bad gjenbruk'!$D21*XLOOKUP('Base case- rivet bad gjenbruk'!$A21,'EPD data'!$A$4:$A$31,'EPD data'!$H$4:$H$31)))} -> 5.48 | H21: {=IF('Base case- rivet bad gjenbruk'!$E21="kg",XLOOKUP(A21,'EPD data'!$A$4:$A$31,'EPD data'!$O$4:$O$31),XLOOKUP(A21,'EPD data'!$A$4:$A$31,'EPD data'!$J$4:$J$31))} -> 21.421 | I21: {=IF('Base case- rivet bad gjenbruk'!$E21="kg",XLOOKUP(A21,'EPD data'!$A$4:$A$31,'EPD data'!$Q$4:$Q$31),XLOOKUP('Base case- rivet bad gjenbruk'!$A21,'EPD data'!$A$4:$A$31,'EPD data'!$L$4:$L$31))} -> 21.823 | J21: {=IF('Base case- rivet bad gjenbruk'!$E21="kg",XLOOKUP('Base case- rivet bad gjenbruk'!$A21,'EPD data'!$A$4:$A$31,'EPD data'!$P$4:$P$31),XLOOKUP('Base case- rivet bad gjenbruk'!$A21,'EPD data'!$A$4:$A$31,'EPD data'!$K$4:$K$31))} -> 0.402 | K21: {=IF('Base case- rivet bad gjenbruk'!$E21="kg",XLOOKUP(A21,'EPD data'!$A$4:$A$31,'EPD data'!$R$4:$R$31),XLOOKUP('Base case- rivet bad gjenbruk'!$A21,'EPD data'!$A$4:$A$31,'EPD data'!$M$4:$M$31))} -> 0.4476 | L21: ='Base case- rivet bad gjenbruk'!$H21*'Base case- rivet bad gjenbruk'!$C21 -> 85.684 | M21: ='Base case- rivet bad gjenbruk'!$J21*'Base case- rivet bad gjenbruk'!$C21 -> 1.608 | N21: =SUM('Base case- rivet bad gjenbruk'!$L21:$M21) -> 87.292 | O21: =IFERROR(K21*C21,0) -> 1.7904 | P21: =IFERROR(H21*$D21,0) -> 85.684 | Q21: =IFERROR('Base case- rivet bad gjenbruk'!$D21*'Base case- rivet bad gjenbruk'!$J21,0) -> 1.608 | R21: ='Base case- rivet bad gjenbruk'!$D21*'Base case- rivet bad gjenbruk'!$I21 -> 87.292 | S21: ='Base case- rivet bad gjenbruk'!$K21*'Base case- rivet bad gjenbruk'!$D21 -> 1.7904 | T21: Downlights SG eco | U21: Notera: vikt refererar till 1 st
A22: Stickkontakt | B22: Plast, kobber stål | C22: 4 | D22: =IF('Base case- rivet bad gjenbruk'!$E22="kg",'Base case- rivet bad gjenbruk'!$C22*$B$3,'Base case- rivet bad gjenbruk'!$C22) -> 4 | E22: pcs | F22: {=IF('Base case- rivet bad gjenbruk'!$E22="kg",'Base case- rivet bad gjenbruk'!$C22,('Base case- rivet bad gjenbruk'!$C22*XLOOKUP('Base case- rivet bad gjenbruk'!$A22,'EPD data'!$A$4:$A$31,'EPD data'!$H$4:$H$31)))} -> 0.484 | G22: {=IF('Base case- rivet bad gjenbruk'!$E22="kg",'Base case- rivet bad gjenbruk'!$D22,('Base case- rivet bad gjenbruk'!$D22*XLOOKUP('Base case- rivet bad gjenbruk'!$A22,'EPD data'!$A$4:$A$31,'EPD data'!$H$4:$H$31)))} -> 0.484 | H22: {=IF('Base case- rivet bad gjenbruk'!$E22="kg",XLOOKUP(A22,'EPD data'!$A$4:$A$31,'EPD data'!$O$4:$O$31),XLOOKUP(A22,'EPD data'!$A$4:$A$31,'EPD data'!$J$4:$J$31))} -> 0.575 | I22: {=IF('Base case- rivet bad gjenbruk'!$E22="kg",XLOOKUP(A22,'EPD data'!$A$4:$A$31,'EPD data'!$Q$4:$Q$31),XLOOKUP('Base case- rivet bad gjenbruk'!$A22,'EPD data'!$A$4:$A$31,'EPD data'!$L$4:$L$31))} -> 0.5906 | J22: {=IF('Base case- rivet bad gjenbruk'!$E22="kg",XLOOKUP('Base case- rivet bad gjenbruk'!$A22,'EPD data'!$A$4:$A$31,'EPD data'!$P$4:$P$31),XLOOKUP('Base case- rivet bad gjenbruk'!$A22,'EPD data'!$A$4:$A$31,'EPD data'!$K$4:$K$31))} -> 0.0156 | K22: {=IF('Base case- rivet bad gjenbruk'!$E22="kg",XLOOKUP(A22,'EPD data'!$A$4:$A$31,'EPD data'!$R$4:$R$31),XLOOKUP('Base case- rivet bad gjenbruk'!$A22,'EPD data'!$A$4:$A$31,'EPD data'!$M$4:$M$31))} -> 0.0213 | L22: ='Base case- rivet bad gjenbruk'!$H22*'Base case- rivet bad gjenbruk'!$C22 -> 2.3 | M22: ='Base case- rivet bad gjenbruk'!$J22*'Base case- rivet bad gjenbruk'!$C22 -> 0.0624 | N22: =SUM('Base case- rivet bad gjenbruk'!$L22:$M22) -> 2.3624 | O22: =IFERROR(K22*C22,0) -> 0.0852 | P22: =IFERROR(H22*$D22,0) -> 2.3 | Q22: =IFERROR('Base case- rivet bad gjenbruk'!$D22*'Base case- rivet bad gjenbruk'!$J22,0) -> 0.0624 | R22: ='Base case- rivet bad gjenbruk'!$D22*'Base case- rivet bad gjenbruk'!$I22 -> 2.3624 | S22: ='Base case- rivet bad gjenbruk'!$K22*'Base case- rivet bad gjenbruk'!$D22 -> 0.0852 | T22: Stikkkontakt Elko plus | U22: Notera: vikt refererar till 1 st
A23: Thermostat | B23: Plast, kobber stål | C23: 1 | D23: =IF('Base case- rivet bad gjenbruk'!$E23="kg",'Base case- rivet bad gjenbruk'!$C23*$B$3,'Base case- rivet bad gjenbruk'!$C23) -> 1 | E23: pcs | F23: {=IF('Base case- rivet bad gjenbruk'!$E23="kg",'Base case- rivet bad gjenbruk'!$C23,('Base case- rivet bad gjenbruk'!$C23*XLOOKUP('Base case- rivet bad gjenbruk'!$A23,'EPD data'!$A$4:$A$31,'EPD data'!$H$4:$H$31)))} -> 2.39 | G23: {=IF('Base case- rivet bad gjenbruk'!$E23="kg",'Base case- rivet bad gjenbruk'!$D23,('Base case- rivet bad gjenbruk'!$D23*XLOOKUP('Base case- rivet bad gjenbruk'!$A23,'EPD data'!$A$4:$A$31,'EPD data'!$H$4:$H$31)))} -> 2.39 | H23: {=IF('Base case- rivet bad gjenbruk'!$E23="kg",XLOOKUP(A23,'EPD data'!$A$4:$A$31,'EPD data'!$O$4:$O$31),XLOOKUP(A23,'EPD data'!$A$4:$A$31,'EPD data'!$J$4:$J$31))} -> 5.62 | I23: {=IF('Base case- rivet bad gjenbruk'!$E23="kg",XLOOKUP(A23,'EPD data'!$A$4:$A$31,'EPD data'!$Q$4:$Q$31),XLOOKUP('Base case- rivet bad gjenbruk'!$A23,'EPD data'!$A$4:$A$31,'EPD data'!$L$4:$L$31))} -> 5.811 | J23: {=IF('Base case- rivet bad gjenbruk'!$E23="kg",XLOOKUP('Base case- rivet bad gjenbruk'!$A23,'EPD data'!$A$4:$A$31,'EPD data'!$P$4:$P$31),XLOOKUP('Base case- rivet bad gjenbruk'!$A23,'EPD data'!$A$4:$A$31,'EPD data'!$K$4:$K$31))} -> 0.191 | K23: {=IF('Base case- rivet bad gjenbruk'!$E23="kg",XLOOKUP(A23,'EPD data'!$A$4:$A$31,'EPD data'!$R$4:$R$31),XLOOKUP('Base case- rivet bad gjenbruk'!$A23,'EPD data'!$A$4:$A$31,'EPD data'!$M$4:$M$31))} -> 0.48955 | L23: ='Base case- rivet bad gjenbruk'!$H23*'Base case- rivet bad gjenbruk'!$C23 -> 5.62 | M23: ='Base case- rivet bad gjenbruk'!$J23*'Base case- rivet bad gjenbruk'!$C23 -> 0.191 | N23: =SUM('Base case- rivet bad gjenbruk'!$L23:$M23) -> 5.811 | O23: =IFERROR(K23*C23,0) -> 0.48955 | P23: =IFERROR(H23*$D23,0) -> 5.62 | Q23: =IFERROR('Base case- rivet bad gjenbruk'!$D23*'Base case- rivet bad gjenbruk'!$J23,0) -> 0.191 | R23: ='Base case- rivet bad gjenbruk'!$D23*'Base case- rivet bad gjenbruk'!$I23 -> 5.811 | S23: ='Base case- rivet bad gjenbruk'!$K23*'Base case- rivet bad gjenbruk'!$D23 -> 0.48955 | T23: Thermostat Elko plus | U23: Notera: vikt refererar till 1 st
A24: Rör till downlight | B24: Plast, kobber stål | C24: 1 | D24: =IF('Base case- rivet bad gjenbruk'!$E24="kg",'Base case- rivet bad gjenbruk'!$C24*$B$3,'Base case- rivet bad gjenbruk'!$C24) -> 6 | E24: kg | F24: {=IF('Base case- rivet bad gjenbruk'!$E24="kg",'Base case- rivet bad gjenbruk'!$C24,('Base case- rivet bad gjenbruk'!$C24*XLOOKUP('Base case- rivet bad gjenbruk'!$A24,'EPD data'!$A$4:$A$31,'EPD data'!$H$4:$H$31)))} -> 1 | G24: {=IF('Base case- rivet bad gjenbruk'!$E24="kg",'Base case- rivet bad gjenbruk'!$D24,('Base case- rivet bad gjenbruk'!$D24*XLOOKUP('Base case- rivet bad gjenbruk'!$A24,'EPD data'!$A$4:$A$31,'EPD data'!$H$4:$H$31)))} -> 6 | H24: {=IF('Base case- rivet bad gjenbruk'!$E24="kg",XLOOKUP(A24,'EPD data'!$A$4:$A$31,'EPD data'!$O$4:$O$31),XLOOKUP(A24,'EPD data'!$A$4:$A$31,'EPD data'!$J$4:$J$31))} -> 4.1337 | I24: {=IF('Base case- rivet bad gjenbruk'!$E24="kg",XLOOKUP(A24,'EPD data'!$A$4:$A$31,'EPD data'!$Q$4:$Q$31),XLOOKUP('Base case- rivet bad gjenbruk'!$A24,'EPD data'!$A$4:$A$31,'EPD data'!$L$4:$L$31))} -> 4.3767 | J24: {=IF('Base case- rivet bad gjenbruk'!$E24="kg",XLOOKUP('Base case- rivet bad gjenbruk'!$A24,'EPD data'!$A$4:$A$31,'EPD data'!$P$4:$P$31),XLOOKUP('Base case- rivet bad gjenbruk'!$A24,'EPD data'!$A$4:$A$31,'EPD data'!$K$4:$K$31))} -> 0.243 | K24: {=IF('Base case- rivet bad gjenbruk'!$E24="kg",XLOOKUP(A24,'EPD data'!$A$4:$A$31,'EPD data'!$R$4:$R$31),XLOOKUP('Base case- rivet bad gjenbruk'!$A24,'EPD data'!$A$4:$A$31,'EPD data'!$M$4:$M$31))} -> 3.04062 | L24: ='Base case- rivet bad gjenbruk'!$H24*'Base case- rivet bad gjenbruk'!$C24 -> 4.1337 | M24: ='Base case- rivet bad gjenbruk'!$J24*'Base case- rivet bad gjenbruk'!$C24 -> 0.243 | N24: =SUM('Base case- rivet bad gjenbruk'!$L24:$M24) -> 4.3767 | O24: =IFERROR(K24*C24,0) -> 3.04062 | P24: =IFERROR(H24*$D24,0) -> 24.8022 | Q24: =IFERROR('Base case- rivet bad gjenbruk'!$D24*'Base case- rivet bad gjenbruk'!$J24,0) -> 1.458 | R24: ='Base case- rivet bad gjenbruk'!$D24*'Base case- rivet bad gjenbruk'!$I24 -> 26.2602 | S24: ='Base case- rivet bad gjenbruk'!$K24*'Base case- rivet bad gjenbruk'!$D24 -> 18.24372 | T24: Korrigert rør | U24: Notera: vikt refererar till 1 st
A25: Våtromsmaling | B25: Maling | C25: 0.6 | D25: =IF('Base case- rivet bad gjenbruk'!$E25="kg",'Base case- rivet bad gjenbruk'!$C25*$B$3,'Base case- rivet bad gjenbruk'!$C25) -> 3.6 | E25: kg | F25: {=IF('Base case- rivet bad gjenbruk'!$E25="kg",'Base case- rivet bad gjenbruk'!$C25,('Base case- rivet bad gjenbruk'!$C25*XLOOKUP('Base case- rivet bad gjenbruk'!$A25,'EPD data'!$A$4:$A$31,'EPD data'!$H$4:$H$31)))} -> 0.6 | G25: {=IF('Base case- rivet bad gjenbruk'!$E25="kg",'Base case- rivet bad gjenbruk'!$D25,('Base case- rivet bad gjenbruk'!$D25*XLOOKUP('Base case- rivet bad gjenbruk'!$A25,'EPD data'!$A$4:$A$31,'EPD data'!$H$4:$H$31)))} -> 3.6 | H25: {=IF('Base case- rivet bad gjenbruk'!$E25="kg",XLOOKUP(A25,'EPD data'!$A$4:$A$31,'EPD data'!$O$4:$O$31),XLOOKUP(A25,'EPD data'!$A$4:$A$31,'EPD data'!$J$4:$J$31))} -> 3.5354 | I25: {=IF('Base case- rivet bad gjenbruk'!$E25="kg",XLOOKUP(A25,'EPD data'!$A$4:$A$31,'EPD data'!$Q$4:$Q$31),XLOOKUP('Base case- rivet bad gjenbruk'!$A25,'EPD data'!$A$4:$A$31,'EPD data'!$L$4:$L$31))} -> 3.5732 | J25: {=IF('Base case- rivet bad gjenbruk'!$E25="kg",XLOOKUP('Base case- rivet bad gjenbruk'!$A25,'EPD data'!$A$4:$A$31,'EPD data'!$P$4:$P$31),XLOOKUP('Base case- rivet bad gjenbruk'!$A25,'EPD data'!$A$4:$A$31,'EPD data'!$K$4:$K$31))} -> 0.0378 | K25: {=IF('Base case- rivet bad gjenbruk'!$E25="kg",XLOOKUP(A25,'EPD data'!$A$4:$A$31,'EPD data'!$R$4:$R$31),XLOOKUP('Base case- rivet bad gjenbruk'!$A25,'EPD data'!$A$4:$A$31,'EPD data'!$M$4:$M$31))} -> 0.01252 | L25: ='Base case- rivet bad gjenbruk'!$H25*'Base case- rivet bad gjenbruk'!$C25 -> 2.12124 | M25: ='Base case- rivet bad gjenbruk'!$J25*'Base case- rivet bad gjenbruk'!$C25 -> 0.02268 | N25: =SUM('Base case- rivet bad gjenbruk'!$L25:$M25) -> 2.14392 | O25: =IFERROR(K25*C25,0) -> 0.007512 | P25: =IFERROR(H25*$D25,0) -> 12.72744 | Q25: =IFERROR('Base case- rivet bad gjenbruk'!$D25*'Base case- rivet bad gjenbruk'!$J25,0) -> 0.13608 | R25: ='Base case- rivet bad gjenbruk'!$D25*'Base case- rivet bad gjenbruk'!$I25 -> 12.86352 | S25: ='Base case- rivet bad gjenbruk'!$K25*'Base case- rivet bad gjenbruk'!$D25 -> 0.045072 | T25: Våtromsmaling | U25: .
A26: Silikon | C26: 0.2 | D26: =IF('Base case- rivet bad gjenbruk'!$E26="kg",'Base case- rivet bad gjenbruk'!$C26*$B$3,'Base case- rivet bad gjenbruk'!$C26) -> 1.2 | E26: kg | F26: {=IF('Base case- rivet bad gjenbruk'!$E26="kg",'Base case- rivet bad gjenbruk'!$C26,('Base case- rivet bad gjenbruk'!$C26*XLOOKUP('Base case- rivet bad gjenbruk'!$A26,'EPD data'!$A$4:$A$31,'EPD data'!$H$4:$H$31)))} -> 0.2 | G26: {=IF('Base case- rivet bad gjenbruk'!$E26="kg",'Base case- rivet bad gjenbruk'!$D26,('Base case- rivet bad gjenbruk'!$D26*XLOOKUP('Base case- rivet bad gjenbruk'!$A26,'EPD data'!$A$4:$A$31,'EPD data'!$H$4:$H$31)))} -> 1.2 | H26: {=IF('Base case- rivet bad gjenbruk'!$E26="kg",XLOOKUP(A26,'EPD data'!$A$4:$A$31,'EPD data'!$O$4:$O$31),XLOOKUP(A26,'EPD data'!$A$4:$A$31,'EPD data'!$J$4:$J$31))} -> 5.36 | I26: {=IF('Base case- rivet bad gjenbruk'!$E26="kg",XLOOKUP(A26,'EPD data'!$A$4:$A$31,'EPD data'!$Q$4:$Q$31),XLOOKUP('Base case- rivet bad gjenbruk'!$A26,'EPD data'!$A$4:$A$31,'EPD data'!$L$4:$L$31))} -> 5.4181 | J26: {=IF('Base case- rivet bad gjenbruk'!$E26="kg",XLOOKUP('Base case- rivet bad gjenbruk'!$A26,'EPD data'!$A$4:$A$31,'EPD data'!$P$4:$P$31),XLOOKUP('Base case- rivet bad gjenbruk'!$A26,'EPD data'!$A$4:$A$31,'EPD data'!$K$4:$K$31))} -> 0.0581 | K26: {=IF('Base case- rivet bad gjenbruk'!$E26="kg",XLOOKUP(A26,'EPD data'!$A$4:$A$31,'EPD data'!$R$4:$R$31),XLOOKUP('Base case- rivet bad gjenbruk'!$A26,'EPD data'!$A$4:$A$31,'EPD data'!$M$4:$M$31))} -> 0.441066 | L26: ='Base case- rivet bad gjenbruk'!$H26*'Base case- rivet bad gjenbruk'!$C26 -> 1.072 | M26: ='Base case- rivet bad gjenbruk'!$J26*'Base case- rivet bad gjenbruk'!$C26 -> 0.01162 | N26: =SUM('Base case- rivet bad gjenbruk'!$L26:$M26) -> 1.08362 | O26: =IFERROR(K26*C26,0) -> 0.0882132 | P26: =IFERROR(H26*$D26,0) -> 6.432 | Q26: =IFERROR('Base case- rivet bad gjenbruk'!$D26*'Base case- rivet bad gjenbruk'!$J26,0) -> 0.06972 | R26: ='Base case- rivet bad gjenbruk'!$D26*'Base case- rivet bad gjenbruk'!$I26 -> 6.50172 | S26: ='Base case- rivet bad gjenbruk'!$K26*'Base case- rivet bad gjenbruk'!$D26 -> 0.5292792 | T26: silikon | U26: .
A27: Fliser | C27: 100 | D27: =IF('Base case- rivet bad gjenbruk'!$E27="kg",'Base case- rivet bad gjenbruk'!$C27*$B$3,'Base case- rivet bad gjenbruk'!$C27) -> 600 | E27: kg | F27: {=IF('Base case- rivet bad gjenbruk'!$E27="kg",'Base case- rivet bad gjenbruk'!$C27,('Base case- rivet bad gjenbruk'!$C27*XLOOKUP('Base case- rivet bad gjenbruk'!$A27,'EPD data'!$A$4:$A$31,'EPD data'!$H$4:$H$31)))} -> 100 | G27: {=IF('Base case- rivet bad gjenbruk'!$E27="kg",'Base case- rivet bad gjenbruk'!$D27,('Base case- rivet bad gjenbruk'!$D27*XLOOKUP('Base case- rivet bad gjenbruk'!$A27,'EPD data'!$A$4:$A$31,'EPD data'!$H$4:$H$31)))} -> 600 | H27: {=IF('Base case- rivet bad gjenbruk'!$E27="kg",XLOOKUP(A27,'EPD data'!$A$4:$A$31,'EPD data'!$O$4:$O$31),XLOOKUP(A27,'EPD data'!$A$4:$A$31,'EPD data'!$J$4:$J$31))} -> 0.52476349 | I27: {=IF('Base case- rivet bad gjenbruk'!$E27="kg",XLOOKUP(A27,'EPD data'!$A$4:$A$31,'EPD data'!$Q$4:$Q$31),XLOOKUP('Base case- rivet bad gjenbruk'!$A27,'EPD data'!$A$4:$A$31,'EPD data'!$L$4:$L$31))} -> 0.54307179 | J27: {=IF('Base case- rivet bad gjenbruk'!$E27="kg",XLOOKUP('Base case- rivet bad gjenbruk'!$A27,'EPD data'!$A$4:$A$31,'EPD data'!$P$4:$P$31),XLOOKUP('Base case- rivet bad gjenbruk'!$A27,'EPD data'!$A$4:$A$31,'EPD data'!$K$4:$K$31))} -> 0.018308292 | K27: {=IF('Base case- rivet bad gjenbruk'!$E27="kg",XLOOKUP(A27,'EPD data'!$A$4:$A$31,'EPD data'!$R$4:$R$31),XLOOKUP('Base case- rivet bad gjenbruk'!$A27,'EPD data'!$A$4:$A$31,'EPD data'!$M$4:$M$31))} -> 0.0047078464 | L27: ='Base case- rivet bad gjenbruk'!$H27*'Base case- rivet bad gjenbruk'!$C27 -> 52.476349 | M27: ='Base case- rivet bad gjenbruk'!$J27*'Base case- rivet bad gjenbruk'!$C27 -> 1.8308292 | N27: =SUM('Base case- rivet bad gjenbruk'!$L27:$M27) -> 54.307179 | O27: =IFERROR(K27*C27,0) -> 0.47078464 | P27: =IFERROR(H27*$D27,0) -> 314.8581 | Q27: =IFERROR('Base case- rivet bad gjenbruk'!$D27*'Base case- rivet bad gjenbruk'!$J27,0) -> 10.984975 | R27: ='Base case- rivet bad gjenbruk'!$D27*'Base case- rivet bad gjenbruk'!$I27 -> 325.84307 | S27: ='Base case- rivet bad gjenbruk'!$K27*'Base case- rivet bad gjenbruk'!$D27 -> 2.8247078 | T27: fliser | U27: .
A28: Flislim og fuger | C28: 4 | D28: =IF('Base case- rivet bad gjenbruk'!$E28="kg",'Base case- rivet bad gjenbruk'!$C28*$B$3,'Base case- rivet bad gjenbruk'!$C28) -> 24 | E28: kg | F28: {=IF('Base case- rivet bad gjenbruk'!$E28="kg",'Base case- rivet bad gjenbruk'!$C28,('Base case- rivet bad gjenbruk'!$C28*XLOOKUP('Base case- rivet bad gjenbruk'!$A28,'EPD data'!$A$4:$A$31,'EPD data'!$H$4:$H$31)))} -> 4 | G28: {=IF('Base case- rivet bad gjenbruk'!$E28="kg",'Base case- rivet bad gjenbruk'!$D28,('Base case- rivet bad gjenbruk'!$D28*XLOOKUP('Base case- rivet bad gjenbruk'!$A28,'EPD data'!$A$4:$A$31,'EPD data'!$H$4:$H$31)))} -> 24 | H28: {=IF('Base case- rivet bad gjenbruk'!$E28="kg",XLOOKUP(A28,'EPD data'!$A$4:$A$31,'EPD data'!$O$4:$O$31),XLOOKUP(A28,'EPD data'!$A$4:$A$31,'EPD data'!$J$4:$J$31))} -> 0.39137 | I28: {=IF('Base case- rivet bad gjenbruk'!$E28="kg",XLOOKUP(A28,'EPD data'!$A$4:$A$31,'EPD data'!$Q$4:$Q$31),XLOOKUP('Base case- rivet bad gjenbruk'!$A28,'EPD data'!$A$4:$A$31,'EPD data'!$L$4:$L$31))} -> 0.41757 | J28: {=IF('Base case- rivet bad gjenbruk'!$E28="kg",XLOOKUP('Base case- rivet bad gjenbruk'!$A28,'EPD data'!$A$4:$A$31,'EPD data'!$P$4:$P$31),XLOOKUP('Base case- rivet bad gjenbruk'!$A28,'EPD data'!$A$4:$A$31,'EPD data'!$K$4:$K$31))} -> 0.0262 | K28: {=IF('Base case- rivet bad gjenbruk'!$E28="kg",XLOOKUP(A28,'EPD data'!$A$4:$A$31,'EPD data'!$R$4:$R$31),XLOOKUP('Base case- rivet bad gjenbruk'!$A28,'EPD data'!$A$4:$A$31,'EPD data'!$M$4:$M$31))} -> 0 | L28: ='Base case- rivet bad gjenbruk'!$H28*'Base case- rivet bad gjenbruk'!$C28 -> 1.56548 | M28: ='Base case- rivet bad gjenbruk'!$J28*'Base case- rivet bad gjenbruk'!$C28 -> 0.1048 | N28: =SUM('Base case- rivet bad gjenbruk'!$L28:$M28) -> 1.67028 | O28: =IFERROR(K28*C28,0) -> 0 | P28: =IFERROR(H28*$D28,0) -> 9.39288 | Q28: =IFERROR('Base case- rivet bad gjenbruk'!$D28*'Base case- rivet bad gjenbruk'!$J28,0) -> 0.6288 | R28: ='Base case- rivet bad gjenbruk'!$D28*'Base case- rivet bad gjenbruk'!$I28 -> 10.02168 | S28: ='Base case- rivet bad gjenbruk'!$K28*'Base case- rivet bad gjenbruk'!$D28 -> 0 | T28: Flislim | U28: .
A29: Sluk og slukrist | B29: Stål,plast | C29: 1 | D29: =IF('Base case- rivet bad gjenbruk'!$E29="kg",'Base case- rivet bad gjenbruk'!$C29*$B$3,'Base case- rivet bad gjenbruk'!$C29) -> 1 | E29: pcs | F29: {=IF('Base case- rivet bad gjenbruk'!$E29="kg",'Base case- rivet bad gjenbruk'!$C29,('Base case- rivet bad gjenbruk'!$C29*XLOOKUP('Base case- rivet bad gjenbruk'!$A29,'EPD data'!$A$4:$A$31,'EPD data'!$H$4:$H$31)))} -> 0.94 | G29: {=IF('Base case- rivet bad gjenbruk'!$E29="kg",'Base case- rivet bad gjenbruk'!$D29,('Base case- rivet bad gjenbruk'!$D29*XLOOKUP('Base case- rivet bad gjenbruk'!$A29,'EPD data'!$A$4:$A$31,'EPD data'!$H$4:$H$31)))} -> 0.94 | H29: {=IF('Base case- rivet bad gjenbruk'!$E29="kg",XLOOKUP(A29,'EPD data'!$A$4:$A$31,'EPD data'!$O$4:$O$31),XLOOKUP(A29,'EPD data'!$A$4:$A$31,'EPD data'!$J$4:$J$31))} -> 0.5272 | I29: {=IF('Base case- rivet bad gjenbruk'!$E29="kg",XLOOKUP(A29,'EPD data'!$A$4:$A$31,'EPD data'!$Q$4:$Q$31),XLOOKUP('Base case- rivet bad gjenbruk'!$A29,'EPD data'!$A$4:$A$31,'EPD data'!$L$4:$L$31))} -> 0.5963 | J29: {=IF('Base case- rivet bad gjenbruk'!$E29="kg",XLOOKUP('Base case- rivet bad gjenbruk'!$A29,'EPD data'!$A$4:$A$31,'EPD data'!$P$4:$P$31),XLOOKUP('Base case- rivet bad gjenbruk'!$A29,'EPD data'!$A$4:$A$31,'EPD data'!$K$4:$K$31))} -> 0.0691 | K29: {=IF('Base case- rivet bad gjenbruk'!$E29="kg",XLOOKUP(A29,'EPD data'!$A$4:$A$31,'EPD data'!$R$4:$R$31),XLOOKUP('Base case- rivet bad gjenbruk'!$A29,'EPD data'!$A$4:$A$31,'EPD data'!$M$4:$M$31))} -> 1.665022 | L29: ='Base case- rivet bad gjenbruk'!$H29*'Base case- rivet bad gjenbruk'!$C29 -> 0.5272 | M29: ='Base case- rivet bad gjenbruk'!$J29*'Base case- rivet bad gjenbruk'!$C29 -> 0.0691 | N29: =SUM('Base case- rivet bad gjenbruk'!$L29:$M29) -> 0.5963 | O29: =IFERROR(K29*C29,0) -> 1.665022 | P29: =IFERROR(H29*$D29,0) -> 0.5272 | Q29: =IFERROR('Base case- rivet bad gjenbruk'!$D29*'Base case- rivet bad gjenbruk'!$J29,0) -> 0.0691 | R29: ='Base case- rivet bad gjenbruk'!$D29*'Base case- rivet bad gjenbruk'!$I29 -> 0.5963 | S29: ='Base case- rivet bad gjenbruk'!$K29*'Base case- rivet bad gjenbruk'!$D29 -> 1.665022 | T29: Sluk (sliderain) | U29: .
A30: Sisterne | B30: Stål (80%), isipor og plast | C30: 1 | D30: =IF('Base case- rivet bad gjenbruk'!$E30="kg",'Base case- rivet bad gjenbruk'!$C30*$B$3,'Base case- rivet bad gjenbruk'!$C30) -> 1 | E30: pcs | F30: {=IF('Base case- rivet bad gjenbruk'!$E30="kg",'Base case- rivet bad gjenbruk'!$C30,('Base case- rivet bad gjenbruk'!$C30*XLOOKUP('Base case- rivet bad gjenbruk'!$A30,'EPD data'!$A$4:$A$31,'EPD data'!$H$4:$H$31)))} -> 13.6 | G30: {=IF('Base case- rivet bad gjenbruk'!$E30="kg",'Base case- rivet bad gjenbruk'!$D30,('Base case- rivet bad gjenbruk'!$D30*XLOOKUP('Base case- rivet bad gjenbruk'!$A30,'EPD data'!$A$4:$A$31,'EPD data'!$H$4:$H$31)))} -> 13.6 | H30: {=IF('Base case- rivet bad gjenbruk'!$E30="kg",XLOOKUP(A30,'EPD data'!$A$4:$A$31,'EPD data'!$O$4:$O$31),XLOOKUP(A30,'EPD data'!$A$4:$A$31,'EPD data'!$J$4:$J$31))} -> 36.8 | I30: {=IF('Base case- rivet bad gjenbruk'!$E30="kg",XLOOKUP(A30,'EPD data'!$A$4:$A$31,'EPD data'!$Q$4:$Q$31),XLOOKUP('Base case- rivet bad gjenbruk'!$A30,'EPD data'!$A$4:$A$31,'EPD data'!$L$4:$L$31))} -> 38.04 | J30: {=IF('Base case- rivet bad gjenbruk'!$E30="kg",XLOOKUP('Base case- rivet bad gjenbruk'!$A30,'EPD data'!$A$4:$A$31,'EPD data'!$P$4:$P$31),XLOOKUP('Base case- rivet bad gjenbruk'!$A30,'EPD data'!$A$4:$A$31,'EPD data'!$K$4:$K$31))} -> 1.24 | K30: {=IF('Base case- rivet bad gjenbruk'!$E30="kg",XLOOKUP(A30,'EPD data'!$A$4:$A$31,'EPD data'!$R$4:$R$31),XLOOKUP('Base case- rivet bad gjenbruk'!$A30,'EPD data'!$A$4:$A$31,'EPD data'!$M$4:$M$31))} -> 11.06163 | L30: ='Base case- rivet bad gjenbruk'!$H30*'Base case- rivet bad gjenbruk'!$C30 -> 36.8 | M30: ='Base case- rivet bad gjenbruk'!$J30*'Base case- rivet bad gjenbruk'!$C30 -> 1.24 | N30: =SUM('Base case- rivet bad gjenbruk'!$L30:$M30) -> 38.04 | O30: =IFERROR(K30*C30,0) -> 11.06163 | P30: =IFERROR(H30*$D30,0) -> 36.8 | Q30: =IFERROR('Base case- rivet bad gjenbruk'!$D30*'Base case- rivet bad gjenbruk'!$J30,0) -> 1.24 | R30: ='Base case- rivet bad gjenbruk'!$D30*'Base case- rivet bad gjenbruk'!$I30 -> 38.04 | S30: =IFERROR('Base case- rivet bad gjenbruk'!$K30*'Base case- rivet bad gjenbruk'!$D30,0) -> 11.06163 | U30: .
A31: Toalett | B31: Porselen | C31: 0 | D31: =IF('Base case- rivet bad gjenbruk'!$E31="kg",'Base case- rivet bad gjenbruk'!$C31*$B$3,'Base case- rivet bad gjenbruk'!$C31) -> 0 | E31: pcs | F31: {=IF('Base case- rivet bad gjenbruk'!$E31="kg",'Base case- rivet bad gjenbruk'!$C31,('Base case- rivet bad gjenbruk'!$C31*XLOOKUP('Base case- rivet bad gjenbruk'!$A31,'EPD data'!$A$4:$A$31,'EPD data'!$H$4:$H$31)))} -> 0 | G31: {=IF('Base case- rivet bad gjenbruk'!$E31="kg",'Base case- rivet bad gjenbruk'!$D31,('Base case- rivet bad gjenbruk'!$D31*XLOOKUP('Base case- rivet bad gjenbruk'!$A31,'EPD data'!$A$4:$A$31,'EPD data'!$H$4:$H$31)))} -> 0 | H31: {=IF('Base case- rivet bad gjenbruk'!$E31="kg",XLOOKUP(A31,'EPD data'!$A$4:$A$31,'EPD data'!$O$4:$O$31),XLOOKUP(A31,'EPD data'!$A$4:$A$31,'EPD data'!$J$4:$J$31))} -> 77.1 | I31: {=IF('Base case- rivet bad gjenbruk'!$E31="kg",XLOOKUP(A31,'EPD data'!$A$4:$A$31,'EPD data'!$Q$4:$Q$31),XLOOKUP('Base case- rivet bad gjenbruk'!$A31,'EPD data'!$A$4:$A$31,'EPD data'!$L$4:$L$31))} -> 77.1 | J31: {=IF('Base case- rivet bad gjenbruk'!$E31="kg",XLOOKUP('Base case- rivet bad gjenbruk'!$A31,'EPD data'!$A$4:$A$31,'EPD data'!$P$4:$P$31),XLOOKUP('Base case- rivet bad gjenbruk'!$A31,'EPD data'!$A$4:$A$31,'EPD data'!$K$4:$K$31))} -> 0 | K31: {=IF('Base case- rivet bad gjenbruk'!$E31="kg",XLOOKUP(A31,'EPD data'!$A$4:$A$31,'EPD data'!$R$4:$R$31),XLOOKUP('Base case- rivet bad gjenbruk'!$A31,'EPD data'!$A$4:$A$31,'EPD data'!$M$4:$M$31))} -> 0.903 | L31: 0 | M31: 0 | N31: 0 | O31: 0 | P31: 0 | Q31: =IFERROR('Base case- rivet bad gjenbruk'!$D31*'Base case- rivet bad gjenbruk'!$J31,0) -> 0 | R31: 0 | S31: 0 | T31: Gustavsberg toalett | U31: Notera: vikt refererar till 1 st. Kan återbrukas.
A32: Dusjevegger | B32: Glass (90%) plast (5%) og stål (5%) | C32: 0 | D32: =IF('Base case- rivet bad gjenbruk'!$E32="kg",'Base case- rivet bad gjenbruk'!$C32*$B$3,'Base case- rivet bad gjenbruk'!$C32) -> 0 | E32: pcs | F32: {=IF('Base case- rivet bad gjenbruk'!$E32="kg",'Base case- rivet bad gjenbruk'!$C32,('Base case- rivet bad gjenbruk'!$C32*XLOOKUP('Base case- rivet bad gjenbruk'!$A32,'EPD data'!$A$4:$A$31,'EPD data'!$H$4:$H$31)))} -> 0 | G32: {=IF('Base case- rivet bad gjenbruk'!$E32="kg",'Base case- rivet bad gjenbruk'!$D32,('Base case- rivet bad gjenbruk'!$D32*XLOOKUP('Base case- rivet bad gjenbruk'!$A32,'EPD data'!$A$4:$A$31,'EPD data'!$H$4:$H$31)))} -> 0 | H32: {=IF('Base case- rivet bad gjenbruk'!$E32="kg",XLOOKUP(A32,'EPD data'!$A$4:$A$31,'EPD data'!$O$4:$O$31),XLOOKUP(A32,'EPD data'!$A$4:$A$31,'EPD data'!$J$4:$J$31))} -> 246 | I32: {=IF('Base case- rivet bad gjenbruk'!$E32="kg",XLOOKUP(A32,'EPD data'!$A$4:$A$31,'EPD data'!$Q$4:$Q$31),XLOOKUP('Base case- rivet bad gjenbruk'!$A32,'EPD data'!$A$4:$A$31,'EPD data'!$L$4:$L$31))} -> 265.5 | J32: {=IF('Base case- rivet bad gjenbruk'!$E32="kg",XLOOKUP('Base case- rivet bad gjenbruk'!$A32,'EPD data'!$A$4:$A$31,'EPD data'!$P$4:$P$31),XLOOKUP('Base case- rivet bad gjenbruk'!$A32,'EPD data'!$A$4:$A$31,'EPD data'!$K$4:$K$31))} -> 19.5 | K32: {=IF('Base case- rivet bad gjenbruk'!$E32="kg",XLOOKUP(A32,'EPD data'!$A$4:$A$31,'EPD data'!$R$4:$R$31),XLOOKUP('Base case- rivet bad gjenbruk'!$A32,'EPD data'!$A$4:$A$31,'EPD data'!$M$4:$M$31))} -> 1.702 | L32: 0 | M32: 0 | N32: 0 | O32: 0 | P32: 0 | Q32: 0 | R32: 0 | S32: 0 | U32: Notera: vikt refererar till 1 st. Kan återbrukas.
A33: Baderomsinnredning | B33: Tre,porselen, plast stål | C33: 0 | D33: =IF('Base case- rivet bad gjenbruk'!$E33="kg",'Base case- rivet bad gjenbruk'!$C33*$B$3,'Base case- rivet bad gjenbruk'!$C33) -> 0 | E33: kg | F33: {=IF('Base case- rivet bad gjenbruk'!$E33="kg",'Base case- rivet bad gjenbruk'!$C33,('Base case- rivet bad gjenbruk'!$C33*XLOOKUP('Base case- rivet bad gjenbruk'!$A33,'EPD data'!$A$4:$A$31,'EPD data'!$H$4:$H$31)))} -> 0 | G33: {=IF('Base case- rivet bad gjenbruk'!$E33="kg",'Base case- rivet bad gjenbruk'!$D33,('Base case- rivet bad gjenbruk'!$D33*XLOOKUP('Base case- rivet bad gjenbruk'!$A33,'EPD data'!$A$4:$A$31,'EPD data'!$H$4:$H$31)))} -> 0 | H33: {=IF('Base case- rivet bad gjenbruk'!$E33="kg",XLOOKUP(A33,'EPD data'!$A$4:$A$31,'EPD data'!$O$4:$O$31),XLOOKUP(A33,'EPD data'!$A$4:$A$31,'EPD data'!$J$4:$J$31))} -> 3.1805 | I33: {=IF('Base case- rivet bad gjenbruk'!$E33="kg",XLOOKUP(A33,'EPD data'!$A$4:$A$31,'EPD data'!$Q$4:$Q$31),XLOOKUP('Base case- rivet bad gjenbruk'!$A33,'EPD data'!$A$4:$A$31,'EPD data'!$L$4:$L$31))} -> 3.1805 | J33: {=IF('Base case- rivet bad gjenbruk'!$E33="kg",XLOOKUP('Base case- rivet bad gjenbruk'!$A33,'EPD data'!$A$4:$A$31,'EPD data'!$P$4:$P$31),XLOOKUP('Base case- rivet bad gjenbruk'!$A33,'EPD data'!$A$4:$A$31,'EPD data'!$K$4:$K$31))} -> 0 | K33: {=IF('Base case- rivet bad gjenbruk'!$E33="kg",XLOOKUP(A33,'EPD data'!$A$4:$A$31,'EPD data'!$R$4:$R$31),XLOOKUP('Base case- rivet bad gjenbruk'!$A33,'EPD data'!$A$4:$A$31,'EPD data'!$M$4:$M$31))} -> 0.0557 | L33: 0 | M33: 0 | N33: 0 | O33: 0 | P33: 0 | Q33: =IFERROR('Base case- rivet bad gjenbruk'!$D33*'Base case- rivet bad gjenbruk'!$J33,0) -> 0 | R33: 0 | S33: 0 | T33: Badekar og dusjkar | U33: Notera: vikt refererar till 1 st. Kan återbrukas.
